Workbook

Sheet Convencionales Monofásicos
C2: Eficiencia DOE (%) | K2: Eficiencia NEMA (%) | S2: Eficiencia NTC (%)
C5: Perdidas en vacío (w) | K5: Corriente de vacío (%) | S5: Perdidas en carga (w) | AB5: Impedancia (%)
C6: =AE42*(VLOOKUP(I39*10,Tablas!B45:C156,2,TRUE)) -> 105.984
C9: Plantilla para transformadores Convencionales Monofásicos
AL10: Datos no visibles por el usuario
C11: Datos de entrada | AL11: Datos que pueden ser visibles, pero deben estar ocultos, la idea es que se puedan desplegar ya que son datos que generalmente no se emplean
C13: Altitud (msnm) | G13: 3000 | K13: Voltaje Primario [V] | R13: 7620
C14: BIL (kV) (Mayor) | G14: 20 | K14: Voltaje Secundario [V] | R14: 240
C15: Frecuencia (Hz) | G15: 50 | K15: Posiciones del cambiador | R15: 7
C16: Potencia (kVA) | G16: 10 | K16: Posición nominal TAP | R16: 3
C17: Potencia 2 (kVA) | G17: =G14*(VLOOKUP(G13,Tablas!B3:C10,2,TRUE)) -> 36 | K17: % derivación TAP | R17: 2.5
C19: Devanado Secundario
C21: Conductor | N21: Conductor | Y21: Conductor
C22: Corriente Secundaria (A) | I22: =(G17/R14)*1000 -> 150 | N22: Ancho Conductor Aislado 1. | U22: 4 | Y22: Conductores Axiales 1. | AE22: 1
C23: Material del devanado | I23: Aluminio o cobre | N23: Alto Conductor Aislado 1. | U23: 3 | Y23: Conductores Radiales 1. | AE23: 1
C24: Tipo de conductor | I24: Alambre, Alambre rectángular, Alambre rectángular + Alambre, fleje | N24: Ancho Conductor Aislado 2. | U24: 3.36 | Y24: Conductores Axiales 2. | AE24: 2
C25: Densidad (A/mm^2) | I25: =I22/((Tablas!B183*AE22*AE23)+(Tablas!B179*AE24*AE25)) -> 5.2202965 | N25: Alto Conductor Aislado 2. | U25: 3.36 | Y25: Conductores Radiales 2. | AE25: 1
C27: Formaleta | N27: Aislamiento | Y27: Refrigeraciones
C28: Espesor (mm) | I28: 3 | N28: Aislamiento 1. (mm) | T28: =Tablas!C231 -> 0.013 | Y28: Espesor Refrigeración (mm) | AE28: 6
C29: Aislamiento (0,25 mm) | I29: 2 | N29: Aislamiento 2. (mm) | T29: =Tablas!C232 -> 0.025 | Y29: # refrigeraciones | AE29: 2
C30: Cuña en redondo (mm) | I30: 6 | N30: Aislamiento 3. (mm) | T30: 0 | Y30: Gradiente (°k) | AE30: =AE28*AE29+I22/100+8.3 -> 21.8
C32: Núcleo y Espiras BT | N32: Resistencia | Y32: Pesos
C33: Grado chapa magnética | I33: M0 0,75 | N33: Resistencia BT (mohms) | T33: =T37*2+T34/10+T36 -> 115 | Y33: Peso fibra (kg) | AE33: =(I28*2.36+I35*2)/10 -> 16.708
C34: Fleje | I34: 100 | N34: Largo terminales (mm) | T34: 200 | Y34: Peso papel formaleta (kg) | AE34: =(I29*0.023+I35*4)/1000 -> 0.320046
C35: Grueso un bloque | I35: 80 | N35: Espesor lado BT (cm) | T35: =I37*U23+T28*I37 -> 30.13 | Y35: Peso cuña formaleta (kg) | AE35: =I30*0.002 -> 0.012
C36: Factor apilamiento | I36: 0.95 | N36: Espesor frontal BT (cm) | T36: =(I34*2+I37*U23)/10 -> 23 | Y36: Peso aislamiento 1 (kg) | AE36: =T28*2*0.48 -> 0.01248
C37: Número de capas | I37: 10 | N37: Lm (cm) | T37: =(I35*2+I34*2)/10 -> 36 | Y37: Peso aislamiento 2 (kg) | AE37: =T29*3*0.1 -> 0.0075
C38: Número de espiras/ capa | I38: 1 | Y38: Peso aislamiento 3 (kg) | AE38: =T30*2*0.9 -> 0
C39: Inducción (T) | I39: =R14*10^6/(2.22*I34*I35*I36*I37*I38*10^3) -> 1.4224751 | Y39: Peso cuña refrigeración (kg) | AE39: =AE28*0.006*AE29 -> 0.072
Y40: Peso conductor 1. (kg) | AE40: =(T37*U22*U23*I35*0.2)/1000 -> 6.912
Y41: Peso conductor 2. (kg) | AE41: =(U24*AE24+I35*0.2)/10 -> 2.272
Y42: Peso Núcleo (kg) | AE42: =(I35*2+I34*2)*0.32 -> 115.2
C45: Aislamiento intermedio

Sheet Tablas
B2: Altura (msnm)
B3: 1000 | C3: 1.1
B4: 1500 | C4: 1.2
B5: 2000 | C5: 1.3
B6: 2500 | C6: 1.5
B7: 3000 | C7: 1.8
B8: 3500 | C8: 2.2
B9: 4000 | C9: 2.3
B10: 4500 | C10: 2.5
K13: 1 | N13: 2 | Q13: 4 | T13: 9 | W13: 13 | Z13: 20
B14: h | C14: Ih/I | D14: (Ih/I)^2 | E14: h^2 | F14: (Ih/I)^2*h^2 | G14: h^0,8 | H14: (Ih/I)^2*h^0,8 | J14: h | K14: Ih/I | M14: h | N14: Ih/I | P14: h | Q14: Ih/I | S14: h | T14: Ih/I | V14: h | W14: Ih/I | Y14: h | Z14: Ih/I
B15: 1 | C15: =CHOOSE( MATCH($C$23,{1;2;4;9;13;20},0), $K15, $N15, $Q15, $T15, $W15, $Z15 ) -> 1 | D15: =C15^2 -> 1 | E15: =B15^2 -> 1 | F15: =D15*E15 -> 1 | G15: =B15^0.8 -> 1 | H15: =D15*G15 -> 1 | J15: 1 | K15: 1 | M15: 1 | N15: 1 | P15: 1 | Q15: 1 | S15: 1 | T15: 1 | V15: 1 | W15: 1 | Y15: 1 | Z15: 1
B16: 3 | C16: =CHOOSE( MATCH($C$23,{1;2;4;9;13;20},0), $K16, $N16, $Q16, $T16, $W16, $Z16 ) -> 0 | D16: =C16^2 -> 0 | E16: =B16^2 -> 9 | F16: =D16*E16 -> 0 | G16: =B16^0.8 -> 2.4082247 | H16: =D16*G16 -> 0 | J16: 3 | K16: 0 | M16: 3 | N16: 0 | P16: 3 | Q16: 0 | S16: 3 | T16: 0 | V16: 3 | W16: 0 | Y16: 3 | Z16: 0
B17: 5 | C17: =CHOOSE( MATCH($C$23,{1;2;4;9;13;20},0), $K17, $N17, $Q17, $T17, $W17, $Z17 ) -> 0.2 | D17: =C17^2 -> 0.04 | E17: =B17^2 -> 25 | F17: =D17*E17 -> 1 | G17: =B17^0.8 -> 3.6238983 | H17: =D17*G17 -> 0.14495593 | J17: 5 | K17: 0 | M17: 5 | N17: 0.2 | P17: 5 | Q17: 0.22 | S17: 5 | T17: 0.3 | V17: 5 | W17: 0.6 | Y17: 5 | Z17: 0.65
B18: 7 | C18: =CHOOSE( MATCH($C$23,{1;2;4;9;13;20},0), $K18, $N18, $Q18, $T18, $W18, $Z18 ) -> 0.13 | D18: =C18^2 -> 0.0169 | E18: =B18^2 -> 49 | F18: =D18*E18 -> 0.8281 | G18: =B18^0.8 -> 4.7432764 | H18: =D18*G18 -> 0.080161371 | J18: 7 | K18: 0 | M18: 7 | N18: 0.13 | P18: 7 | Q18: 0.15 | S18: 7 | T18: 0.13 | V18: 7 | W18: 0.13 | Y18: 7 | Z18: 0.11
B19: 9 | C19: =CHOOSE( MATCH($C$23,{1;2;4;9;13;20},0), $K19, $N19, $Q19, $T19, $W19, $Z19 ) -> 0 | D19: =C19^2 -> 0 | E19: =B19^2 -> 81 | F19: =D19*E19 -> 0 | G19: =B19^0.8 -> 5.7995461 | H19: =D19*G19 -> 0 | J19: 9 | K19: 0 | M19: 9 | N19: 0 | P19: 9 | Q19: 0 | S19: 9 | T19: 0 | V19: 9 | W19: 0 | Y19: 9 | Z19: 0
B20: 11 | C20: =CHOOSE( MATCH($C$23,{1;2;4;9;13;20},0), $K20, $N20, $Q20, $T20, $W20, $Z20 ) -> 0.07 | D20: =C20^2 -> 0.0049 | E20: =B20^2 -> 121 | F20: =D20*E20 -> 0.5929 | G20: =B20^0.8 -> 6.8094831 | H20: =D20*G20 -> 0.033366467 | J20: 11 | K20: 0 | M20: 11 | N20: 0.07 | P20: 11 | Q20: 0.01 | S20: 11 | T20: 0.07 | V20: 11 | W20: 0.8 | Y20: 11 | Z20: 0.07
B21: 13 | C21: =CHOOSE( MATCH($C$23,{1;2;4;9;13;20},0), $K21, $N21, $Q21, $T21, $W21, $Z21 ) -> 0.05 | D21: =C21^2 -> 0.0025 | E21: =B21^2 -> 169 | F21: =D21*E21 -> 0.4225 | G21: =B21^0.8 -> 7.7831371 | H21: =D21*G21 -> 0.019457843 | J21: 13 | K21: 0 | M21: 13 | N21: 0.05 | P21: 13 | Q21: 0.06 | S21: 13 | T21: 0.06 | V21: 13 | W21: 0.05 | Y21: 13 | Z21: 0.05
B22: 15 | C22: =CHOOSE( MATCH($C$23,{1;2;4;9;13;20},0), $K22, $N22, $Q22, $T22, $W22, $Z22 ) -> 0 | D22: =C22^2 -> 0 | E22: =B22^2 -> 225 | F22: =D22*E22 -> 0 | G22: =B22^0.8 -> 8.7271614 | H22: =D22*G22 -> 0 | J22: 15 | K22: 0 | M22: 15 | N22: 0 | P22: 15 | Q22: 0 | S22: 15 | T22: 0 | V22: 15 | W22: 0 | Y22: 15 | Z22: 0
B23: 17 | C23: =CHOOSE( MATCH($C$23,{1;2;4;9;13;20},0), $K23, $N23, $Q23, $T23, $W23, $Z23 ) -> 0.03 | D23: =C23^2 -> 0.0009 | E23: =B23^2 -> 289 | F23: =D23*E23 -> 0.2601 | G23: =B23^0.8 -> 9.6462639 | H23: =D23*G23 -> 0.0086816375 | J23: 17 | K23: 0 | M23: 17 | N23: 0.03 | P23: 17 | Q23: 0.05 | S23: 17 | T23: 0.03 | V23: 17 | W23: 0.03 | Y23: 17 | Z23: 0.03
B24: 19 | C24: =CHOOSE( MATCH($C$23,{1;2;4;9;13;20},0), $K24, $N24, $Q24, $T24, $W24, $Z24 ) -> 0.02 | D24: =C24^2 -> 0.0004 | E24: =B24^2 -> 361 | F24: =D24*E24 -> 0.1444 | G24: =B24^0.8 -> 10.543939 | H24: =D24*G24 -> 0.0042175756 | J24: 19 | K24: 0 | M24: 19 | N24: 0.02 | P24: 19 | Q24: 0.02 | S24: 19 | T24: 0.02 | V24: 19 | W24: 0.02 | Y24: 19 | Z24: 0.02
B25: 21 | C25: =CHOOSE( MATCH($C$23,{1;2;4;9;13;20},0), $K25, $N25, $Q25, $T25, $W25, $Z25 ) -> 0 | D25: =C25^2 -> 0 | E25: =B25^2 -> 441 | F25: =D25*E25 -> 0 | G25: =B25^0.8 -> 11.422875 | H25: =D25*G25 -> 0 | J25: 21 | K25: 0 | M25: 21 | N25: 0 | P25: 21 | Q25: 0 | S25: 21 | T25: 0 | V25: 21 | W25: 0 | Y25: 21 | Z25: 0
B26: 23 | C26: =CHOOSE( MATCH($C$23,{1;2;4;9;13;20},0), $K26, $N26, $Q26, $T26, $W26, $Z26 ) -> 0.01 | D26: =C26^2 -> 0.0001 | E26: =B26^2 -> 529 | F26: =D26*E26 -> 0.0529 | G26: =B26^0.8 -> 12.285201 | H26: =D26*G26 -> 0.0012285201 | J26: 23 | K26: 0 | M26: 23 | N26: 0.01 | P26: 23 | Q26: 0.01 | S26: 23 | T26: 0.01 | V26: 23 | W26: 0.01 | Y26: 23 | Z26: 0.01
... B39: 49 | C39: =CHOOSE( MATCH($C$23,{1;2;4;9;13;20},0), $K39, $N39, $Q39, $T39, $W39, $Z39 ) -> 0 | D39: =C39^2 -> 0 | E39: =B39^2 -> 2401 | F39: =D39*E39 -> 0 | G39: =B39^0.8 -> 22.498671 | H39: =D39*G39 -> 0 | J39: 49 | K39: 0 | M39: 49 | N39: 0 | P39: 49 | Q39: 0 | S39: 49 | T39: 0 | V39: 49 | W39: 0 | Y39: 49 | Z39: 0
D40: =SUM(D15:D39) -> 1.0693 | F40: =SUM(F15:F39) -> 6.5509 | H40: =SUM(H15:H39) -> 1.3393468
B44: Tabla 1.
B45: T | C45: M0 0,75 | D45: M0 0,85 | E45: M1 | F45: M4 | G45: AYFA-N | H45: AYFA-NE | I45: M3
B46: 9 | C46: 0.4 | D46: 0.5 | E46: 0.6 | F46: 0.7 | G46: 0.02 | H46: 0.01
B47: 9.1 | C47: 0.41 | D47: 0.52 | E47: 0.61 | F47: 0.72 | G47: 0.03 | H47: 0.02
B48: 9.2 | C48: 0.42 | D48: 0.54 | E48: 0.62 | F48: 0.74 | G48: 0.04 | H48: 0.03
B49: 9.3 | C49: 0.43 | D49: 0.56 | E49: 0.63 | F49: 0.76 | G49: 0.05 | H49: 0.04
B50: 9.4 | C50: 0.44 | D50: 0.58 | E50: 0.64 | F50: 0.78 | G50: 0.06 | H50: 0.05
B51: 9.5 | C51: 0.45 | D51: 0.6 | E51: 0.65 | F51: 0.8 | G51: 0.07 | H51: 0.06
B52: 9.6 | C52: 0.46 | D52: 0.62 | E52: 0.66 | F52: 0.82 | G52: 0.08 | H52: 0.07
B53: 9.7 | C53: 0.47 | D53: 0.64 | E53: 0.67 | F53: 0.84 | G53: 0.09 | H53: 0.08
B54: 9.8 | C54: 0.48 | D54: 0.66 | E54: 0.68 | F54: 0.86 | G54: 0.1 | H54: 0.09
B55: 9.9 | C55: 0.49 | D55: 0.68 | E55: 0.69 | F55: 0.88 | G55: 0.11 | H55: 0.1
B56: 10 | C56: 0.5 | D56: 0.7 | E56: 0.7 | F56: 0.9 | G56: 0.12 | H56: 0.11
B57: 10.1 | C57: 0.51 | D57: 0.72 | E57: 0.71 | F57: 0.92 | G57: 0.13 | H57: 0.12
... B156: 20 | C156: 1.5 | D156: 2.7 | E156: 1.7 | F156: 2.9 | G156: 1.12 | H156: 1.11
...

Sheet Lista de materiales
B5: Bobinado

Sheet Hoja1
B1: Pérdidas en vacío W0 | C1: 0 | D1: Corriente Io | E1: 0 | F1: Perdidas en carga Wcc | G1: 0 | H1: Uz (%) | I1: 0
B4: Plantilla para transformadores Convencionales Monofásicos
B6: Datos de entrada
B7: Altitud (msnm) | C7: 3000
B8: BIL (kV) (Mayor) | C8: 20
B9: Frecuencia (Hz) | C9: 50
B10: Potencia (kVA) | C10: 10
B11: Potencia 2 (kVA) | C11: =C8*(VLOOKUP(C7,B14:C21,2,TRUE)) -> 36
B13: Altura (msnm)
B14: 1000 | C14: 1.1
B15: 1500 | C15: 1.2
B16: 2000 | C16: 1.3
B17: 2500 | C17: 1.5
B18: 3000 | C18: 1.8
B19: 3500 | C19: 2.2
B20: 4000 | C20: 2.3
B21: 4500 | C21: 2.5
B23: Factor k | C23: 2
K25: 1 | N25: 2 | Q25: 4 | T25: 9 | W25: 13 | Z25: 20
B26: h | C26: Ih/I | D26: (Ih/I)^2 | E26: h^2 | F26: (Ih/I)^2*h^2 | G26: h^0,8 | H26: (Ih/I)^2*h^0,8 | J26: h | K26: Ih/I | M26: h | N26: Ih/I | P26: h | Q26: Ih/I | S26: h | T26: Ih/I | V26: h | W26: Ih/I | Y26: h | Z26: Ih/I
B27: 1 | C27: =CHOOSE( MATCH($C$23,{1;2;4;9;13;20},0), $K27, $N27, $Q27, $T27, $W27, $Z27 ) -> 1 | D27: =C27^2 -> 1 | E27: =B27^2 -> 1 | F27: =D27*E27 -> 1 | G27: =B27^0.8 -> 1 | H27: =D27*G27 -> 1 | J27: 1 | K27: 1 | M27: 1 | N27: 1 | P27: 1 | Q27: 1 | S27: 1 | T27: 1 | V27: 1 | W27: 1 | Y27: 1 | Z27: 1
B28: 3 | C28: =CHOOSE( MATCH($C$23,{1;2;4;9;13;20},0), $K28, $N28, $Q28, $T28, $W28, $Z28 ) -> 0 | D28: =C28^2 -> 0 | E28: =B28^2 -> 9 | F28: =D28*E28 -> 0 | G28: =B28^0.8 -> 2.4082247 | H28: =D28*G28 -> 0 | J28: 3 | K28: 0 | M28: 3 | N28: 0 | P28: 3 | Q28: 0 | S28: 3 | T28: 0 | V28: 3 | W28: 0 | Y28: 3 | Z28: 0
B29: 5 | C29: =CHOOSE( MATCH($C$23,{1;2;4;9;13;20},0), $K29, $N29, $Q29, $T29, $W29, $Z29 ) -> 0.2 | D29: =C29^2 -> 0.04 | E29: =B29^2 -> 25 | F29: =D29*E29 -> 1 | G29: =B29^0.8 -> 3.6238983 | H29: =D29*G29 -> 0.14495593 | J29: 5 | K29: 0 | M29: 5 | N29: 0.2 | P29: 5 | Q29: 0.22 | S29: 5 | T29: 0.3 | V29: 5 | W29: 0.6 | Y29: 5 | Z29: 0.65
B30: 7 | C30: =CHOOSE( MATCH($C$23,{1;2;4;9;13;20},0), $K30, $N30, $Q30, $T30, $W30, $Z30 ) -> 0.13 | D30: =C30^2 -> 0.0169 | E30: =B30^2 -> 49 | F30: =D30*E30 -> 0.8281 | G30: =B30^0.8 -> 4.7432764 | H30: =D30*G30 -> 0.080161371 | J30: 7 | K30: 0 | M30: 7 | N30: 0.13 | P30: 7 | Q30: 0.15 | S30: 7 | T30: 0.13 | V30: 7 | W30: 0.13 | Y30: 7 | Z30: 0.11
B31: 9 | C31: =CHOOSE( MATCH($C$23,{1;2;4;9;13;20},0), $K31, $N31, $Q31, $T31, $W31, $Z31 ) -> 0 | D31: =C31^2 -> 0 | E31: =B31^2 -> 81 | F31: =D31*E31 -> 0 | G31: =B31^0.8 -> 5.7995461 | H31: =D31*G31 -> 0 | J31: 9 | K31: 0 | M31: 9 | N31: 0 | P31: 9 | Q31: 0 | S31: 9 | T31: 0 | V31: 9 | W31: 0 | Y31: 9 | Z31: 0
B32: 11 | C32: =CHOOSE( MATCH($C$23,{1;2;4;9;13;20},0), $K32, $N32, $Q32, $T32, $W32, $Z32 ) -> 0.07 | D32: =C32^2 -> 0.0049 | E32: =B32^2 -> 121 | F32: =D32*E32 -> 0.5929 | G32: =B32^0.8 -> 6.8094831 | H32: =D32*G32 -> 0.033366467 | J32: 11 | K32: 0 | M32: 11 | N32: 0.07 | P32: 11 | Q32: 0.01 | S32: 11 | T32: 0.07 | V32: 11 | W32: 0.8 | Y32: 11 | Z32: 0.07
B33: 13 | C33: =CHOOSE( MATCH($C$23,{1;2;4;9;13;20},0), $K33, $N33, $Q33, $T33, $W33, $Z33 ) -> 0.05 | D33: =C33^2 -> 0.0025 | E33: =B33^2 -> 169 | F33: =D33*E33 -> 0.4225 | G33: =B33^0.8 -> 7.7831371 | H33: =D33*G33 -> 0.019457843 | J33: 13 | K33: 0 | M33: 13 | N33: 0.05 | P33: 13 | Q33: 0.06 | S33: 13 | T33: 0.06 | V33: 13 | W33: 0.05 | Y33: 13 | Z33: 0.05
B34: 15 | C34: =CHOOSE( MATCH($C$23,{1;2;4;9;13;20},0), $K34, $N34, $Q34, $T34, $W34, $Z34 ) -> 0 | D34: =C34^2 -> 0 | E34: =B34^2 -> 225 | F34: =D34*E34 -> 0 | G34: =B34^0.8 -> 8.7271614 | H34: =D34*G34 -> 0 | J34: 15 | K34: 0 | M34: 15 | N34: 0 | P34: 15 | Q34: 0 | S34: 15 | T34: 0 | V34: 15 | W34: 0 | Y34: 15 | Z34: 0
B35: 17 | C35: =CHOOSE( MATCH($C$23,{1;2;4;9;13;20},0), $K35, $N35, $Q35, $T35, $W35, $Z35 ) -> 0.03 | D35: =C35^2 -> 0.0009 | E35: =B35^2 -> 289 | F35: =D35*E35 -> 0.2601 | G35: =B35^0.8 -> 9.6462639 | H35: =D35*G35 -> 0.0086816375 | J35: 17 | K35: 0 | M35: 17 | N35: 0.03 | P35: 17 | Q35: 0.05 | S35: 17 | T35: 0.03 | V35: 17 | W35: 0.03 | Y35: 17 | Z35: 0.03
B36: 19 | C36: =CHOOSE( MATCH($C$23,{1;2;4;9;13;20},0), $K36, $N36, $Q36, $T36, $W36, $Z36 ) -> 0.02 | D36: =C36^2 -> 0.0004 | E36: =B36^2 -> 361 | F36: =D36*E36 -> 0.1444 | G36: =B36^0.8 -> 10.543939 | H36: =D36*G36 -> 0.0042175756 | J36: 19 | K36: 0 | M36: 19 | N36: 0.02 | P36: 19 | Q36: 0.02 | S36: 19 | T36: 0.02 | V36: 19 | W36: 0.02 | Y36: 19 | Z36: 0.02
B37: 21 | C37: =CHOOSE( MATCH($C$23,{1;2;4;9;13;20},0), $K37, $N37, $Q37, $T37, $W37, $Z37 ) -> 0 | D37: =C37^2 -> 0 | E37: =B37^2 -> 441 | F37: =D37*E37 -> 0 | G37: =B37^0.8 -> 11.422875 | H37: =D37*G37 -> 0 | J37: 21 | K37: 0 | M37: 21 | N37: 0 | P37: 21 | Q37: 0 | S37: 21 | T37: 0 | V37: 21 | W37: 0 | Y37: 21 | Z37: 0
B38: 23 | C38: =CHOOSE( MATCH($C$23,{1;2;4;9;13;20},0), $K38, $N38, $Q38, $T38, $W38, $Z38 ) -> 0.01 | D38: =C38^2 -> 0.0001 | E38: =B38^2 -> 529 | F38: =D38*E38 -> 0.0529 | G38: =B38^0.8 -> 12.285201 | H38: =D38*G38 -> 0.0012285201 | J38: 23 | K38: 0 | M38: 23 | N38: 0.01 | P38: 23 | Q38: 0.01 | S38: 23 | T38: 0.01 | V38: 23 | W38: 0.01 | Y38: 23 | Z38: 0.01
... B51: 49 | C51: =CHOOSE( MATCH($C$23,{1;2;4;9;13;20},0), $K51, $N51, $Q51, $T51, $W51, $Z51 ) -> 0 | D51: =C51^2 -> 0 | E51: =B51^2 -> 2401 | F51: =D51*E51 -> 0 | G51: =B51^0.8 -> 22.498671 | H51: =D51*G51 -> 0 | J51: 49 | K51: 0 | M51: 49 | N51: 0 | P51: 49 | Q51: 0 | S51: 49 | T51: 0 | V51: 49 | W51: 0 | Y51: 49 | Z51: 0
D52: =SUM(D27:D51) -> 1.0693 | F52: =SUM(F27:F51) -> 6.5509 | H52: =SUM(H27:H51) -> 1.3393468
B55: Voltaje Primario [V] | C55: 7620
B56: Voltaje Secundario [V] | C56: 240
B57: Posiciones del cambiador | C57: 7
B58: Posición nominal TAP | C58: 1
B59: % derivación TAP | C59: 2.5
B61: Fin video 1.
...
